Workbook

Sheet 資產負債表
A1: 公司名稱 | B1: 年度 | C1: 現金及約當現金 | D1: 應收票據 | E1: 應收帳款 | F1: 應收帳款-關係人淨額 | G1: 其他應收款 | H1: 其他應收款-關係人 | I1: 本期所得税資產 | J1: 存貨 | K1: 預付款項 | L1: 其他流動資產 | M1: 流動資產 | N1: 不動產、廠房及設備 | O1: 使用權資產 | P1: 其他無形資產 | Q1: 遞延所得税資產 | R1: 存出保證金 | S1: 其他金融資產-非流動 | T1: 其他非流動資產 | U1: 非流動資產 | V1: 資產 | W1: 短期借款 | X1: 合約負債一流動 | Y1: 應付帳款 | Z1: 應付帳款-關係人 | AA1: 其他應付款 | AB1: 本期所得税負債 | AC1: 租賃負債-流動 | AD1: 其他流動負債 | AE1: 流動負債 | AF1: 合約負債-非流動 | AG1: 遞延所得税負債 | AH1: 租賃負債-非流動 | AI1: 淨確定福利負債一非流動 | AJ1: 存入保證金 | AK1: 非流動負債 | AL1: 負債 | AM1: 普通股股本 | AN1: 資本公積 | AO1: 法定盈餘公積 | AP1: 未分配盈餘 | AQ1: 其他權益 | AR1: 權益
A2: 博弘雲端 | B2: 2024 | C2: 720946 | D2: 20145 | E2: 708366 | F2: 42144 | G2: 0 | H2: 0 | I2: 2996 | J2: 114 | K2: 87497 | L2: 113 | M2: 1582321 | N2: 1069 | O2: 2325 | P2: 6 | Q2: 3701 | R2: 8965 | S2: 290 | T2: 8473 | U2: 24829 | V2: 1607150 | W2: 0 | X2: 224024 | Y2: 531111 | Z2: 0 | AA2: 102968 | AB2: 19264 | AC2: 1925 | AD2: 22938 | AE2: 902230 | AF2: 15189 | AG2: 28308 | AH2: 0 | AI2: 484 | AJ2: 32651 | AK2: 76632 | AL2: 978862 | AM2: 221005 | AN2: 255519 | AO2: 20632 | AP2: 123175 | AQ2: 7957 | AR2: 628288
A3: 博弘雲端 | B3: 2023 | C3: 640349 | D3: 17352 | E3: 632626 | F3: 43476 | G3: 0 | H3: 0 | I3: 0 | J3: 110 | K3: 144883 | L3: 317 | M3: 1479113 | N3: 4548 | O3: 16061 | P3: 486 | Q3: 4288 | R3: 7992 | S3: 290 | T3: 18650 | U3: 52315 | V3: 1531428 | W3: 0 | X3: 297556 | Y3: 695116 | Z3: 0 | AA3: 85082 | AB3: 7043 | AC3: 14966 | AD3: 22660 | AE3: 1122423 | AF3: 29180 | AG3: 16212 | AH3: 0 | AI3: 0 | AJ3: 27124 | AK3: 72516 | AL3: 1194939 | AM3: 200115 | AN3: 32399 | AO3: 11599 | AP3: 90431 | AQ3: 1945 | AR3: 336489
A4: 博弘雲端 | B4: 2022 | C4: 363448 | D4: 11703 | E4: 788636 | F4: 63401 | G4: 0 | H4: 0 | I4: 4573 | J4: 301 | K4: 135313 | L4: 158 | M4: 1367533 | N4: 7200 | O4: 32122 | P4: 1272 | Q4: 2576 | R4: 6704 | S4: 290 | T4: 11272 | U4: 61436 | V4: 1428969 | W4: 20000 | X4: 221860 | Y4: 779314 | Z4: 0 | AA4: 69937 | AB4: 11925 | AC4: 16007 | AD4: 23365 | AE4: 1142408 | AF4: 22793 | AG4: 6942 | AH4: 16334 | AI4: 0 | AJ4: 11951 | AK4: 58020 | AL4: 1200428 | AM4: 159490 | AN4: 0 | AO4: 5533 | AP4: 60969 | AQ4: 2549 | AR4: 228541
A5: 博弘雲端 | B5: 2021 | C5: 385677 | D5: 8223 | E5: 546750 | F5: 34079 | G5: 656 | H5: 0 | I5: 0 | J5: 202 | K5: 104767 | L5: 572 | M5: 1080926 | N5: 3483 | O5: 5503 | P5: 1831 | Q5: 4066 | R5: 5558 | S5: 0 | T5: 7021 | U5: 27462 | V5: 1108388 | W5: 0 | X5: 147076 | Y5: 676292 | Z5: 0 | AA5: 55181 | AB5: 16064 | AC5: 1872 | AD5: 15706 | AE5: 912191 | AF5: 6641 | AG5: 7404 | AH5: 3778 | AI5: 0 | AJ5: 13845 | AK5: 31668 | AL5: 943859 | AM5: 49000 | AN5: 61000 | AO5: 0 | AP5: 55331 | AQ5: -802 | AR5: 164529
A6: 博弘雲端 | B6: 2020 | C6: 152500 | D6: 8837 | E6: 369271 | F6: 23402 | G6: 2470 | H6: 3889 | I6: 0 | J6: 495 | K6: 68691 | L6: 519 | M6: 630074 | N6: 1491 | O6: 6356 | P6: 650 | Q6: 2055 | R6: 5651 | S6: 0 | T6: 0 | U6: 16203 | V6: 646277 | W6: 30000 | X6: 70048 | Y6: 341513 | Z6: 22575 | AA6: 36519 | AB6: 6941 | AC6: 6466 | AD6: 10003 | AE6: 524065 | AF6: 0 | AG6: 1642 | AH6: 0 | AI6: 0 | AJ6: 15864 | AK6: 17506 | AL6: 541571 | AM6: 49000 | AN6: 61000 | AO6: 0 | AP6: -4931 | AQ6: -363 | AR6: 104706

Sheet 損益表
A1: 公司名稱 | B1: 年度 | C1: 營業收入淨額 | D1: 營業成本 | E1: 營業毛利 | F1: 營業費用 | G1: 推銷費用 | H1: 管理費用 | I1: 研究發展費用 | J1: 預期信用減損迴轉利益 | K1: 營業淨利 | L1: 營業外收入及支出 | M1: 外幣淨兌換損益 | N1: 利息收入 | O1: 財務成本 | P1: 其他利益及損失 | Q1: 税前淨利 | R1: 所得稅費用 | S1: 本年度淨利 | T1: 確定福利計畫之再衡量数 | U1: 與不重分類之項目相關之所得稅 | V1: 國外營運機構財務報表換算之兌換差額 | W1: 與可能重分類之項目相關之所得稅 | X1: 其他綜合損益 | Y1: 本年度綜合損益總額 | Z1: 基本每股盈餘 | AA1: 稀釋每股盈餘
A2: 博弘雲端 | B2: 2024 | C2: 4002787 | D2: 3509063 | E2: 493724 | F2: 338457 | G2: 204265 | H2: 111761 | I2: 24996 | J2: 2565 | K2: 155267 | L2: 5841 | M2: -3712 | N2: 9598 | O2: -182 | P2: 137 | Q2: 161108 | R2: 38071 | S2: 123037 | T2: -18 | U2: 4 | V2: 7515 | W2: -1503 | X2: 5998 | Y2: 129035 | Z2: 6.11 | AA2: 6.09
A3: 博弘雲端 | B3: 2023 | C3: 4748542 | D3: 4327051 | E3: 421491 | F3: 307257 | G3: 177418 | H3: 103871 | I3: 17531 | J3: -8437 | K3: 114234 | L3: 6792 | M3: 153 | N3: 6879 | O3: -656 | P3: 416 | Q3: 121026 | R3: 30698 | S3: 90328 | T3: 0 | U3: 0 | V3: -755 | W3: 151 | X3: -604 | Y3: 89724 | Z3: 4.6 | AA3: 4.57
A4: 博弘雲端 | B4: 2022 | C4: 5061879 | D4: 4655463 | E4: 406416 | F4: 311523 | G4: 185313 | H4: 72803 | I4: 15286 | J4: -38121 | K4: 94893 | L4: -15771 | M4: -16168 | N4: 417 | O4: -445 | P4: 425 | Q4: 79122 | R4: 18461 | S4: 60661 | V4: 4188 | W4: -837 | X4: 3351 | Y4: 64012 | Z4: 3.8 | AA4: 3.79
A5: 博弘雲端 | B5: 2021 | C5: 3510759 | D5: 3190920 | E5: 319839 | F5: 226148 | G5: 150525 | H5: 48881 | I5: 7852 | J5: -18890 | K5: 93691 | L5: -10633 | M5: -7132 | N5: 57 | O5: -295 | P5: -3263 | Q5: 83058 | R5: 22796 | S5: 60262 | V5: -548 | W5: 109 | X5: -439 | Y5: 59823 | Z5: 3.78 | AA5: 3.76
A6: 博弘雲端 | B6: 2020 | C6: 2066623 | D6: 1855975 | E6: 210648 | F6: 164504 | G6: 118794 | H6: 32375 | I6: 5316 | J6: -8019 | K6: 46144 | L6: 3272 | M6: 1224 | N6: 66 | O6: -323 | P6: 2305 | Q6: 49416 | R6: 10898 | S6: 38518 | V6: -371 | W6: 74 | X6: -297 | Y6: 38221 | Z6: 2.42 | AA6: 2.42

Sheet 財報分析
A1: 年度 | B1: 公司別 | C1: 淨利率 | D1: 毛利率 | E1: ROA | F1: 流動比率 | G1: 速動比率 | H1: 負債淨值比 | I1: 應收帳款週轉率 | J1: 存貨周轉率 | K1: 營收成長率 | L1: 毛利成長率 | M1: 稅前淨利成長率 | N1: 推銷費用占比 | O1: 管理費用佔比 | P1: 研發費用佔比
A2: 2024 | B2: 博弘雲端 | C2: =損益表!Q2/損益表!C2 -> 0.040248957 | D2: =損益表!E2/損益表!C2 -> 0.12334506 | E2: =損益表!S2/((資產負債表!V2+資產負債表!V3)/2) -> 0.078403022 | F2: =資產負債表!M2/資產負債表!AE2 -> 1.7537889 | G2: =(資產負債表!M2-資產負債表!K2-資產負債表!J2)/資產負債表!AE2 -> 1.656684 | H2: =資產負債表!AL2/資產負債表!AR2 -> 1.557983 | I2: =損益表!C2/(((資產負債表!D2+資產負債表!E2+資產負債表!F2)+(資產負債表!D3+資產負債表!E3+資產負債表!F3))/2) -> 5.4678811 | J2: =損益表!D2/((資產負債表!J2+資產負債表!J3)/2) -> 31330.92 | K2: =損益表!C2/損益表!C3-1 -> -0.15704926 | L2: =損益表!E2/損益表!E3-1 -> 0.17137495 | M2: =損益表!Q2/損益表!Q3-1 -> 0.33118503 | N2: =損益表!G2/損益表!C2 -> 0.051030694 | O2: =損益表!H2/損益表!C2 -> 0.027920796 | P2: =損益表!I2/損益表!C2 -> 0.006244649
A3: 2023 | B3: 博弘雲端 | C3: =損益表!Q3/損益表!C3 -> 0.025486981 | D3: =損益表!E3/損益表!C3 -> 0.088762193 | E3: =損益表!S3/((資產負債表!V3+資產負債表!V4)/2) -> 0.061024248 | F3: =資產負債表!M3/資產負債表!AE3 -> 1.3177857 | G3: =(資產負債表!M3-資產負債表!K3-資產負債表!J3)/資產負債表!AE3 -> 1.1886071 | H3: =資產負債表!AL3/資產負債表!AR3 -> 3.5511978 | I3: =損益表!C3/(((資產負債表!D3+資產負債表!E3+資產負債表!F3)+(資產負債表!D4+資產負債表!E4+資產負債表!F4))/2) -> 6.0988445 | J3: =損益表!D3/((資產負債表!J3+資產負債表!J4)/2) -> 21056.209 | K3: =損益表!C3/損益表!C4-1 -> -0.061901322 | L3: =損益表!E3/損益表!E4-1 -> 0.037092536 | M3: =損益表!Q3/損益表!Q4-1 -> 0.5296125 | N3: =損益表!G3/損益表!C3 -> 0.037362626 | O3: =損益表!H3/損益表!C3 -> 0.021874293 | P3: =損益表!I3/損益表!C3 -> 0.0036918701
A4: 2022 | B4: 博弘雲端 | C4: =損益表!Q4/損益表!C4 -> 0.015630954 | D4: =損益表!E4/損益表!C4 -> 0.080289553 | E4: =損益表!S4/((資產負債表!V4+資產負債表!V5)/2) -> 0.04781432 | F4: =資產負債表!M4/資產負債表!AE4 -> 1.1970618 | G4: =(資產負債表!M4-資產負債表!K4-資產負債表!J4)/資產負債表!AE4 -> 1.0783529 | H4: =資產負債表!AL4/資產負債表!AR4 -> 5.2525717 | I4: =損益表!C4/(((資產負債表!D4+資產負債表!E4+資產負債表!F4)+(資產負債表!D5+資產負債表!E5+資產負債表!F5))/2) -> 6.9684841 | J4: =損益表!D4/((資產負債表!J4+資產負債表!J5)/2) -> 18510.787 | K4: =損益表!C4/損益表!C5-1 -> 0.44181899 | L4: =損益表!E4/損益表!E5-1 -> 0.27068932 | M4: =損益表!Q4/損益表!Q5-1 -> -0.047388572 | N4: =損益表!G4/損益表!C4 -> 0.036609528 | O4: =損益表!H4/損益表!C4 -> 0.014382604 | P4: =損益表!I4/損益表!C4 -> 0.0030198272
A5: 2021 | B5: 博弘雲端 | C5: =損益表!Q5/損益表!C5 -> 0.023658132 | D5: =損益表!E5/損益表!C5 -> 0.091102522 | E5: =損益表!S5/((資產負債表!V5+資產負債表!V6)/2) -> 0.068687755 | F5: =資產負債表!M5/資產負債表!AE5 -> 1.1849777 | G5: =(資產負債表!M5-資產負債表!K5-資產負債表!J5)/資產負債表!AE5 -> 1.0699042 | H5: =資產負債表!AL5/資產負債表!AR5 -> 5.7367333 | I5: =損益表!C5/(((資產負債表!D5+資產負債表!E5+資產負債表!F5)+(資產負債表!D6+資產負債表!E6+資產負債表!F6))/2) -> 7.0884185 | J5: =損益表!D5/((資產負債表!J5+資產負債表!J6)/2) -> 9156.1549 | K5: =損益表!C5/損益表!C6-1 -> 0.69879025 | L5: =損益表!E5/損益表!E6-1 -> 0.51835764 | M5: =損益表!Q5/損益表!Q6-1 -> 0.68079165 | N5: =損益表!G5/損益表!C5 -> 0.042875344 | O5: =損益表!H5/損益表!C5 -> 0.0139232 | P5: =損益表!I5/損益表!C5 -> 0.0022365534

Sheet 財務比率說明
A1: 指標 | B1: 計算公式 | C1: 判斷基礎 | D1: 正面 / 負面
A2: 淨利率 | B2: 税前淨利 / 營業收入淨額 | C2: 大於10% | D2: 正面
C3: 小於0% | D3: 負面
C4: 前一年度<0%，本年度>0% | D4: 正面
C5: 前一年度>0%，本年度<0% | D5: 負面
C6: 連續三年以上<0% | D6: 負面
A7: 毛利率 | B7: 營業毛利 / 營業收入淨額 | C7: 大於10% | D7: 正面
C8: 小於0% | D8: 負面
C9: 本年度 < 前一年度 | D9: 負面
C10: 本年度 > 前一年度 | D10: 正面
A11: ROA | B11: 本年度淨利 / ( (資產 + 前一年度資產) / 2 ) | C11: 大於10% | D11: 正面
C12: 小於5% | D12: 負面
C13: 小於0% | D13: 負面
C14: 連續三年皆呈現正成長 | D14: 正面
A15: 流動比率 | B15: 流動資產 / 流動負債 | C15: 大於2 | D15: 正面
C16: 小於1 | D16: 負面
C17: 大於1且速動比率>0.8 | D17: 正面
C18: 前一年度<1，本年度>1 | D18: 正面
C19: 前一年度>1，本年度<1 | D19: 負面
A20: 速動比率 | B20: (流動資產 - 存貨 - 預付款項) / 流動負債 | C20: 大於0.8 | D20: 正面
C21: 小於0.8 | D21: 負面
C22: 前一年度<0.8，本年度>0.8 | D22: 正面
C23: 前一年度>0.8，本年度<0.8 | D23: 負面
A24: 負債淨值比 | B24: 負債 / 權益 | C24: 大於200% | D24: 負面
C25: 小於100% | D25: 正面
C26: 連續三年皆呈現正成長 | D26: 負面
A27: 應收帳款週轉率 | B27: 營業收入淨額 / (今年和去年(應收票據 + 應收帳款 +應收帳款-關係人淨額)/2) | C27: 大於6 | D27: 正面
C28: 小於4 | D28: 負面
C29: 連續三年皆呈現負成長 | D29: 負面
A30: 存貨周轉率 | B30: 營業成本 / ((存貨 + 去年度存貨)/2) | C30: 大於4 | D30: 正面
C31: 小於2 | D31: 負面
C32: 連續三年皆呈現負成長 | D32: 負面
A33: 營收成長率 | B33: 營業收入淨額 / 前一年度營業收入淨額 - 1 | C33: 大於10% | D33: 正面
C34: 小於0% | D34: 負面
C35: 連續三年>10% | D35: 正面
C36: 連續三年<0% | D36: 負面
A37: 毛利成長率 | B37: 營業毛利 / 前一年度營業毛利 -1 | C37: 連續三年皆呈現負成長 | D37: 負面
C38: 連續三年皆呈現正成長 | D38: 正面
C39: 成長幅度超過5% | D39: 正面
C40: 衰退幅度超過5% | D40: 負面
...
